Workbook
Name CorDaCélula: 'ABERTURA DE REQUISIÇÃO'!$O$12

Sheet ABERTURA DE REQUISIÇÃO
A1: EMPRESA | B1: FILIAL | C1: LOJA | D1: CNPJ | E1: COORDENADOR | F1: PROJETO | G1: SERVIÇO | H1: NOTA | I1: FORNECEDOR | J1: ORDEM | K1: REQUISIÇÃO | L1: VALOR | M1: STATUS | N1: PEDIDO | O1: TICKET | P1: STATUS PGTO | Q1: DATA PGTO | R1: MIRO | S1: PENDENTE | T1: data criação linha
B2: 56 | C2: FOR191-15Novembro-CE | D2: 06.626.253/0056-25 | E2: Jordana | F2: LOJAS NOVAS | G2: UTILITES LOJAS NOVAS | H2: ORÇ | I2: ALVO-K | J2: 603700 | K2: 10020172 | L2: 1800 | M2: ENVIADO | T2: 45677
B3: 56 | C3: FOR191-15Novembro-CE | D3: 06.626.253/0056-25 | E3: Jordana | F3: LOJAS NOVAS | G3: UTILITES LOJAS NOVAS | H3: ORÇ | I3: ALVO-K | J3: 603700 | K3: 10020172 | L3: 4015 | M3: ENVIADO | T3: 45677
B4: 513 | C4: CGD23-TrêsBarras-MS | D4: 06.626.253/0513-09 | E4: ANDRE | F4: LOJAS NOVAS | G4: UTILITES LOJAS NOVAS | H4: 5431 | I4: ALVO-K | J4: 603320 | K4: 10020213 | L4: 2000 | M4: ENVIADO | T4: 45677
B5: 513 | C5: CGD23-TrêsBarras-MS | D5: 06.626.253/0513-09 | E5: ANDRE | F5: LOJAS NOVAS | G5: UTILITES LOJAS NOVAS | H5: 5432 | I5: ALVO-K | J5: 603320 | K5: 10020214 | L5: 18800 | M5: ENVIADO | T5: 45677
B6: 1372 | C6: REC74-LuizNunes-PE | D6: 06.626.253/1372-97 | E6: Jordana | F6: LOJAS NOVAS | G6: UTILITES LOJAS NOVAS | H6: 5445 | I6: ALVO-K | J6: 603125 | K6: 10020215 | L6: 1800 | M6: ENVIADO | T6: 45677
B7: 1372 | C7: REC74-LuizNunes-PE | D7: 06.626.253/1372-97 | E7: Jordana | F7: LOJAS NOVAS | G7: UTILITES LOJAS NOVAS | H7: 5446 | I7: ALVO-K | J7: 603125 | K7: 10020216 | L7: 4015 | M7: ENVIADO | T7: 45677
B8: 1372 | C8: REC74-LuizNunes-PE | D8: 06.626.253/1372-97 | E8: Jordana | F8: LOJAS NOVAS | G8: UTILITES LOJAS NOVAS | H8: 5447 | I8: ALVO-K | J8: 603125 | K8: 10020217 | L8: 10350 | M8: ENVIADO | T8: 45677
B9: 1432 | C9: REC72-AntFalcao-PE | D9: 06.626.253/1432-62 | E9: Jordana | F9: LOJAS NOVAS | G9: UTILITES LOJAS NOVAS | H9: 5442 | I9: ALVO-K | J9: 603254 | K9: 10020218 | L9: 1800 | M9: ENVIADO | T9: 45677
B10: 1432 | C10: REC72-AntFalcao-PE | D10: 06.626.253/1432-62 | E10: Jordana | F10: LOJAS NOVAS | G10: UTILITES LOJAS NOVAS | H10: 5443 | I10: ALVO-K | J10: 603254 | K10: 10020219 | L10: 4015 | M10: ENVIADO | T10: 45677
B11: 1432 | C11: REC72-AntFalcao-PE | D11: 06.626.253/1432-62 | E11: Jordana | F11: LOJAS NOVAS | G11: UTILITES LOJAS NOVAS | H11: 5444 | I11: ALVO-K | J11: 603254 | K11: 10020230 | L11: 12500 | M11: ENVIADO | T11: 45677
B12: 1440 | C12: OEI01-Oeiras-PI | D12: 1440 | E12: ANDRE | F12: LOJAS NOVAS | G12: UTILITES LOJAS NOVAS | H12: 5435 | I12: ALVO-K | J12: 602883 | K12: 10020231 | L12: 1800 | M12: ENVIADO | T12: 45677
B13: 1440 | C13: OEI01-Oeiras-PI | D13: 1440 | E13: ANDRE | F13: LOJAS NOVAS | G13: UTILITES LOJAS NOVAS | H13: 5436 | I13: ALVO-K | J13: 602883 | K13: 10020232 | L13: 4015 | M13: ENVIADO | T13: 45677
B14: 1440 | C14: OEI01-Oeiras-PI | D14: 1440 | E14: ANDRE | F14: LOJAS NOVAS | G14: UTILITES LOJAS NOVAS | H14: 5437 | I14: ALVO-K | J14: 602883 | K14: 10020233 | L14: 2000 | M14: ENVIADO | T14: 45677
B15: 1440 | C15: OEI01-Oeiras-PI | D15: 1440 | E15: ANDRE | F15: LOJAS NOVAS | G15: UTILITES LOJAS NOVAS | H15: 5438 | I15: ALVO-K | J15: 602883 | K15: 10020234 | L15: 12500 | M15: ENVIADO | T15: 45677
B16: 1455 | C16: VAR06-JoaoPonce-MT | D16: 06.626.253/1455-59 | E16: Jordana | F16: LOJAS NOVAS | G16: UTILITES LOJAS NOVAS | H16: 5448 | I16: ALVO-K | J16: 603908 | K16: 10020235 | L16: 1800 | M16: ENVIADO | T16: 45677
B17: 1455 | C17: VAR06-JoaoPonce-MT | D17: 06.626.253/1455-59 | E17: Jordana | F17: LOJAS NOVAS | G17: UTILITES LOJAS NOVAS | H17: 5449 | I17: ALVO-K | J17: 603908 | K17: 10020236 | L17: 4015 | M17: ENVIADO | T17: 45677
B18: 1455 | C18: VAR06-JoaoPonce-MT | D18: 06.626.253/1455-59 | E18: Jordana | F18: LOJAS NOVAS | G18: UTILITES LOJAS NOVAS | H18: 5450 | I18: ALVO-K | J18: 603908 | K18: 10020237 | L18: 2000 | M18: ENVIADO | T18: 45677
B19: 1455 | C19: VAR06-JoaoPonce-MT | D19: 06.626.253/1455-59 | E19: Jordana | F19: LOJAS NOVAS | G19: UTILITES LOJAS NOVAS | H19: 5451 | I19: ALVO-K | J19: 603908 | K19: 10020238 | L19: 1800 | M19: ENVIADO | T19: 45677
B20: 1461 | C20: PRB03-Liberdade-PA | D20: 1461 | E20: Henrique | F20: LOJAS NOVAS | G20: UTILITES LOJAS NOVAS | H20: 5439 | I20: ALVO-K | J20: 603682 | K20: 10020239 | L20: 1800 | M20: ENVIADO | T20: 45677
B21: 1461 | C21: PRB03-Liberdade-PA | D21: 1461 | E21: Henrique | F21: LOJAS NOVAS | G21: UTILITES LOJAS NOVAS | H21: 5440 | I21: ALVO-K | J21: 603682 | K21: 10020240 | L21: 4015 | M21: ENVIADO | T21: 45677
B22: 1461 | C22: PRB03-Liberdade-PA | D22: 1461 | E22: Henrique | F22: LOJAS NOVAS | G22: UTILITES LOJAS NOVAS | H22: 5441 | I22: ALVO-K | J22: 603682 | K22: 10020241 | L22: 12500 | M22: ENVIADO | T22: 45677
B23: 1464 | C23: JPE50-FcoLeocadio-PB | D23: 1464 | E23: ANDRE | F23: LOJAS NOVAS | G23: UTILITES LOJAS NOVAS | H23: ORÇ | I23: ALVO-K | J23: 604010 | K23: 10020242 | L23: 1800 | M23: ENVIADO | T23: 45677
B24: 1464 | C24: JPE50-FcoLeocadio-PB | D24: 1464 | E24: ANDRE | F24: LOJAS NOVAS | G24: UTILITES LOJAS NOVAS | H24: ORÇ | I24: ALVO-K | J24: 604010 | K24: 10020243 | L24: 2000 | M24: ENVIADO | T24: 45677
B25: 1464 | C25: JPE50-FcoLeocadio-PB | D25: 1464 | E25: ANDRE | F25: LOJAS NOVAS | G25: UTILITES LOJAS NOVAS | H25: ORÇ | I25: ALVO-K | J25: 604010 | K25: 10020244 | L25: 4015 | M25: ENVIADO | T25: 45677
B26: 1464 | C26: JPE50-FcoLeocadio-PB | D26: 1464 | E26: ANDRE | F26: LOJAS NOVAS | G26: UTILITES LOJAS NOVAS | H26: ORÇ | I26: ALVO-K | J26: 604010 | K26: 10020245 | L26: 10350 | M26: ENVIADO | T26: 45677
B27: 1479 | C27: FOR192-AlCraveiro-CE | D27: 06.626.253/1479-26 | E27: Jordana | F27: LOJAS NOVAS | G27: UTILITES LOJAS NOVAS | H27: ORÇ | I27: ALVO-K | J27: 603708 | K27: 10020175 | L27: 4015 | M27: RECEBIDO | T27: 45677
B28: 1481 | C28: BJS02-ManoelLeite-CE. | D28: 06.626.253/0264-60 | E28: Jordana | F28: LOJAS NOVAS | G28: UTILITES LOJAS NOVAS | H28: ORÇ | I28: ALVO-K | J28: 603999 | K28: 10020246 | L28: 1800 | M28: ENVIADO | T28: 45677
B29: 1481 | C29: BJS02-ManoelLeite-CE. | D29: 06.626.253/0264-60 | E29: Jordana | F29: LOJAS NOVAS | G29: UTILITES LOJAS NOVAS | H29: ORÇ | I29: ALVO-K | J29: 603999 | K29: 10020247 | L29: 4015 | M29: ENVIADO | T29: 45677
B30: 1481 | C30: BJS02-ManoelLeite-CE. | D30: 06.626.253/0264-60 | E30: Jordana | F30: LOJAS NOVAS | G30: UTILITES LOJAS NOVAS | H30: ORÇ | I30: ALVO-K | J30: 603999 | K30: 10020248 | L30: 10350 | M30: ENVIADO | T30: 45677
B31: 140 | C31: MAC02-PontaVerde-AL | D31: =IFERROR(_xlfn.XLOOKUP(B31,'CNPJ LN'!C:C,'CNPJ LN'!D:D),_xlfn.XLOOKUP(B31,'CNPJ BASE jan25'!A:A,'CNPJ BASE jan25'!B:B)) -> MAC02-PontaVerde-AL | E31: ANDRE | F31: LAUDO DE RISCO | G31: REFORMA | H31: ORÇ | I31: BRUNO FANTINATI | J31: 605316 | K31: 10020113 | L31: 5600 | M31: RECEBIDO | N31: 4500776900 | T31: 45645
B32: 7178 | C32: CMT02-CeRaiLea-PA-EF | D32: =IFERROR(_xlfn.XLOOKUP(B32,'CNPJ LN'!C:C,'CNPJ LN'!D:D),_xlfn.XLOOKUP(B32,'CNPJ BASE jan25'!A:A,'CNPJ BASE jan25'!B:B)) -> CMT02-CeRaiLea-PA-EF | E32: ANDRE | F32: VIRADA DE BANDEIRA | G32: REFORMA | H32: ORÇ | I32: CARMELLI | J32: 605492 | K32: 10019999 | L32: 90000 | M32: RECEBIDO | N32: 4500776896 | T32: 45645
B33: 37 | C33: 37-FOR19-VirgTavora-CE | D33: 06.626.253/0037-62 | E33: JORDANA | F33: LAUDO DE RISCO | G33: PINTURA DE FAIXADA | H33: ORÇ | I33: CHIANCA | J33: 604821 | L33: R$ 14.347,98 | M33: RECEBIDO | T33: 45645
B34: 299 | C34: FOR117-SolonPinhe-CE | D34: 06.626.253/1408-32 | E34: JORDANA | F34: LAUDO DE RISCO | G34: PINTURA DE FAIXADA | H34: ORÇ | I34: CHIANCA | J34: 604824 | K34: 10019783 | L34: 8397.35 | M34: RECEBIDO | T34: 45645
B35: 1408 | C35: FOR123-GodMaciel4-CE | D35: 06.626.253/0299-90 | E35: JORDANA | F35: LAUDO DE RISCO | G35: RECUPERAÇÃO ESTACIONAMENTO | H35: ORÇ | I35: CHIANCA | J35: 605518 | L35: R$ 48.053,68 | M35: RECEBIDO | T35: 45645
B36: 79 | C36: SLU01-SaoLuis-MA# | D36: =IFERROR(_xlfn.XLOOKUP(B36,'CNPJ LN'!C:C,'CNPJ LN'!D:D),_xlfn.XLOOKUP(B36,'CNPJ BASE jan25'!A:A,'CNPJ BASE jan25'!B:B)) -> SLU01-SaoLuis-MA# | E36: ANDRE | F36: LAUDO DE RISCO | G36: REFORMA | H36: ORÇ | I36: DWA | J36: 605535 | K36: 10020105 | L36: 50699.453 | M36: RECEBIDO | N36: 4500772073 | T36: 45645
B37: 7054 | C37: SLU45-ColMor49-MA-EF | D37: =IFERROR(_xlfn.XLOOKUP(B37,'CNPJ LN'!C:C,'CNPJ LN'!D:D),_xlfn.XLOOKUP(B37,'CNPJ BASE jan25'!A:A,'CNPJ BASE jan25'!B:B)) -> SLU45-ColMor49-MA-EF | E37: ANDRE | F37: LAUDO DE RISCO | G37: REFORMA | H37: ORÇ | I37: DWA | J37: 605161 | K37: 10020106 | L37: 9706.5912 | M37: RECEBIDO | N37: 4500776912 | T37: 45645
B38: 7107 | C38: SLU50-JerDAlb2-MA-EF | D38: =IFERROR(_xlfn.XLOOKUP(B38,'CNPJ LN'!C:C,'CNPJ LN'!D:D),_xlfn.XLOOKUP(B38,'CNPJ BASE jan25'!A:A,'CNPJ BASE jan25'!B:B)) -> SLU50-JerDAlb2-MA-EF | E38: ANDRE | F38: LAUDO DE RISCO | G38: REFORMA | H38: ORÇ | I38: DWA | J38: 605160 | K38: 10020114 | L38: 13577.88 | M38: RECEBIDO | N38: 4500776904 | T38: 45645
B39: 7174 | C39: SLU58-JoMiJo21-MA-EF | D39: =IFERROR(_xlfn.XLOOKUP(B39,'CNPJ LN'!C:C,'CNPJ LN'!D:D),_xlfn.XLOOKUP(B39,'CNPJ BASE jan25'!A:A,'CNPJ BASE jan25'!B:B)) -> SLU58-JoMiJo21-MA-EF | E39: ANDRE | F39: LAUDO DE RISCO | G39: REFORMA | H39: ORÇ | I39: DWA | J39: 605162 | K39: 10020107 | L39: 5469.29 | M39: RECEBIDO | N39: 4500776915 | T39: 45645
B40: 56 | C40: FOR30-GomesMatos-CE | D40: =IFERROR(_xlfn.XLOOKUP(B40,'CNPJ LN'!C:C,'CNPJ LN'!D:D),_xlfn.XLOOKUP(B40,'CNPJ BASE jan25'!A:A,'CNPJ BASE jan25'!B:B)) -> FOR30-GomesMatos-CE | E40: JORDANA | F40: LOJAS NOVAS | G40: GERENCIAMENTO | H40: 14413 | I40: HTB | J40: 603700 | K40: 10020084 | L40: 36750 | M40: RECEBIDO | T40: 45645
...

Sheet CNPJ LN
B1: Site | C1: COD | D1: CNPJ | E1: Loja Espelho | F1: Endereço
A2: =_xlfn.XLOOKUP(B2,'SOLICITAÇÃO DE PAGAMENTO'!C:C,'SOLICITAÇÃO DE PAGAMENTO'!E:E) -> JORDANA | B2: FOR191-15Novembro-CE | C2: 1484 | D2: 06.626.253/1484-93 | E2: 06.626.253/0056-25 | F2: Rua 15 de Novembro, 340 – Montese – Fortaleza - CE
A3: =_xlfn.XLOOKUP(B3,'SOLICITAÇÃO DE PAGAMENTO'!C:C,'SOLICITAÇÃO DE PAGAMENTO'!E:E) -> JORDANA | B3: FOR192-AlCraveiro-CE | C3: 1479 | D3: 06.626.253/1479-26 | E3: 06.626.253/0616-14 | F3: Av. Alberto Craveiro, 116 - Boa Vista Castelão, Fortaleza - CE
A4: =_xlfn.XLOOKUP(B4,'SOLICITAÇÃO DE PAGAMENTO'!C:C,'SOLICITAÇÃO DE PAGAMENTO'!E:E) -> HENRIQUE | B4: PRB03-Liberdade-PA | C4: 1461 | D4: 06.626.253/1461-05 | F4: Av. Liberdade, 202, Bairro Da Paz, Parauapebas - PA
A5: =_xlfn.XLOOKUP(B5,'SOLICITAÇÃO DE PAGAMENTO'!C:C,'SOLICITAÇÃO DE PAGAMENTO'!E:E) -> ANDRE | B5: OEI01-Oeiras-PI | C5: 1440 | D5: 06.626.253/1440-72 | E5: 06.626.253/1222-65 | F5: Av. José Tapety, 77, Centro, Oeiras - PI
A6: =_xlfn.XLOOKUP(B6,'SOLICITAÇÃO DE PAGAMENTO'!C:C,'SOLICITAÇÃO DE PAGAMENTO'!E:E) -> JORDANA | B6: REC74-LuizNunes-PE | C6: 1372 | D6: 06.626.253/1372-97 | E6: 06.626.253/0147-05 | F6: Rua Arquiteto Luiz Nunes, 1556 – Imbiribeira
A7: =_xlfn.XLOOKUP(B7,'SOLICITAÇÃO DE PAGAMENTO'!C:C,'SOLICITAÇÃO DE PAGAMENTO'!E:E) -> ANDRE | B7: CGD23-TrêsBarras-MS | C7: 1483 | D7: 06.626.253/1483-02 | F7: Av. Três Barras, 1038 - Vila Vilas Boas, Campo Grande - MS
A8: =_xlfn.XLOOKUP(B8,'SOLICITAÇÃO DE PAGAMENTO'!C:C,'SOLICITAÇÃO DE PAGAMENTO'!E:E) -> JORDANA | B8: VAR06-JoaoPonce-MT | C8: 1455 | D8: 06.626.253/1455-59 | F8: Av. João Ponce de Arruda, 170 - Centro Norte - Várzea Grande - MT
A9: =_xlfn.XLOOKUP(B9,'SOLICITAÇÃO DE PAGAMENTO'!C:C,'SOLICITAÇÃO DE PAGAMENTO'!E:E) -> JORDANA | B9: REC72-AntFalcao-PE | C9: 1432 | D9: 06.626.253/1432-62 | E9: 06.626.253/0134-82 | F9: R. Antônio Falcão, 438 - Boa Viagem, Recife - PE
B10: BJS02-ManuelLeite-CE | C10: 1481 | D10: 06.626.253/1481-40 | F10: R. Manoel Leite de Moura, 498 - Centro, Brejo Santo - CE
A11: JORDANA | B11: PDL01-Paudalho-PE | C11: 1462 | D11: 06.626.253/1462-88 | F11: R. Sen. Pinheiro Ramos, 369C - Centro, Paudalho - PE
B12: AJU30-GetulioVarg-SE | C12: 1012 | D12: 06.626.253/1012-68 | E12: 06.626.253/0827-00 | F12: Avenida Augusto Franco, 2500 – Ponto Novo
A13: =_xlfn.XLOOKUP(B13,'SOLICITAÇÃO DE PAGAMENTO'!C:C,'SOLICITAÇÃO DE PAGAMENTO'!E:E) -> ANDRE | B13: MAC26-Aldebaran-AL | C13: 1381 | D13: 06.626.253/1381-88 | E13: 06.626.253/0186-03 | F13: Rua José Alfredo Marques, 41 – Antares
B14: SAL64-ShBahia-BA
A15: =_xlfn.XLOOKUP(B15,'SOLICITAÇÃO DE PAGAMENTO'!C:C,'SOLICITAÇÃO DE PAGAMENTO'!E:E) -> HENRIQUE | B15: RBR13-VilaIvonete-AC | C15: 1446 | D15: 06.626.253/1446-68 | F15: Av. Antônio da Rocha Viana, 5225 - Vila Ivonete, Rio Branco - AC
B16: CRA05-CelAntLuiz-CE | C16: 1480 | D16: 06.626.253/1480-60 | F16: Rua Cel. Antonio Luiz, 1323 - Pimenta, Crato - CE
B17: TER31-CasteloPiaui-PI | C17: 1473 | D17: 06.626.253/1473-30 | F17: Rua Castelo do Piauí, 3.232, Qd. V, Buenos Aires, Teresina - PI
A18: ANDRE | B18: JPE50-FcoLeocardio-PB | C18: 1464 | D18: 06.626.253/1464-40 | F18: R. Francisco Leocádio Ribeiro Coutinho, S/N - Aeroclube, João Pessoa - PB
B19: CRU10-LeãoDourado-PE | C19: 1369 | D19: 06.626.253/1369-91 | E19: 06.626.253/0552-15 | F19: Avenida Leão Dourado, 222 – São Francisco
B20: SLU78-JoaoPessoa-MA | C20: 1439 | D20: 06.626.253/1439-39 | E20: 06.626.253/1045-26 | F20: Av. João Pessoa, 266-A - Jordoa, São Luís - MA
B21: SLU79-Cajazeiras-MA | E21: 06.626.253/0080-55 | F21: Av. Cajazeiras, 44, Centro, São Luís - MA
B22: JGU11-Montarroyos-PE | C22: 1427 | D22: 06.626.253/1427-03 | E22: 06.626.253/0602-19 | F22: Av. Ulisses Montarroyos, 2898, Piedade, Jaboatão dos Guararapes -PE
B23: JGU14-CuradoII-PE | C23: 400 | D23: 06.626.253/0400-21 | E23: 06.626.253/0923-31 | F23: R. Leonardo da Vinci, 1 - Curado, Recife - PE
B24: JGU15-AnicetoV-PE | C24: 1457 | D24: 06.626.253/1457-10 | F24: Rua Cuiabá, 992, Candeias
B25: PAR08-Rdosventos-RN | C25: 1460 | D25: 06.626.253/1460-16 | F25: Rua Cândido Martins dos Santos, 348, Parnamirim- RN
B26: SLU75-Holandeses-MA | C26: 1476 | D26: 06.626.253/1476-83 | F26: Av. Dos Holandeses, 1803, Ponta D’Areia, São Luís - MA
B27: SLU81-ArturCarval-MA | E27: 06.626.253/1077-03 | F27: Rua General Artur Carvalho, S/N, Turu, São Luís - MA
B28: SLU82-StDumont-MA | F28: Av. Santos Dumont, 21, Qd. 262, Lote 21, Alameda dos Sonhos, São Luís - MA
B29: SLU83-JAlbuquerqu-MA | F29: Av. Jerônimo de Albuquerque, 2.255, Cohama
B30: SLU84-Africanos-MA | C30: 1472 | D30: 06.626.253/1472-50 | F30: Av. dos Africanos, 163 - Coroado
B31: TER32-15deNov-PI | C31: 1475 | D31: 06.626.253/1475-00 | F31: Rua Rodrigues Alves, S/N, Lourival Parente
B32: AGU01-AguaBranca-PI
B33: ALT02-Brasilia-PA
B34: CGD-JMurtinho-MS
B35: CHP02-15Novembro-MA
B36: JBA06-CountryClub-BA
B37: SMG01-SaoMiguelGuama-PA
B38: TAM01-Tamandaré-PE
B39: TUC02-JMarilucy-PA
B40: FOR195-SaoCristovao-CE
...

Sheet CNPJ BASE jan25
A1: COD_LOJA | B1: NOME_LOJA | C1: CNPJ
A2: 1 | B2: FOR01-Fortaleza-CE# | C2: 06.626.253/0001-51
A3: 2 | B3: FOR02-BezMenezes-CE# | C3: 06.626.253/0002-32
A4: 3 | B4: FOR03-Abolicao-CE | C4: 06.626.253/0003-13
A5: 4 | B5: FOR04-BrStudart-CE# | C5: 06.626.253/0004-02
A6: 5 | B6: TIN01-Tiangua-CE# | C6: 06.626.253/0005-85
A7: 6 | B7: SOB01-Sobral-CE | C7: 06.626.253/0006-66
A8: 7 | B8: FOR35-OtavioBonfi-CE | C8: 06.626.253/0007-47
A9: 8 | B9: PAC01-Pacajus-CE# | C9: 06.626.253/0008-28
A10: 9 | B10: FOR05-ShAldeota-CE# | C10: 06.626.253/0009-09
A11: 10 | B11: FOR87-CelCarvalh-CE# | C11: 06.626.253/0010-42
A12: 11 | B12: FOR06-AlbertoMag-CE# | C12: 06.626.253/0011-23
A13: 12 | B13: FOR07-JoseWalter-CE# | C13: 06.626.253/0012-04
... A502: 512 | B502: SFI02-WashingtoL-BA | C502: 06.626.253/0512-28
A503: 513 | B503: CGD05-StaDorothe-MS# | C503: 06.626.253/0513-09 | D503: nota
A504: 514 | B504: CGD06-Guanandi-MS# | C504: 06.626.253/0514-90
A505: 515 | B505: GOV01-GValadares-MG# | C505: 06.626.253/0515-70
A506: 516 | B506: FOR61-Expedicion-CE# | C506: 06.626.253/0516-51
A507: 517 | B507: POA03-LimaeSilva-RS | C507: 06.626.253/0517-32
A508: 518 | B508: AJU07-Laranjeiras-SE | C508: 06.626.253/0518-13
A509: 519 | B509: VAR01-VarzeaGran-MT# | C509: 06.626.253/0519-02
A510: 520 | B510: IGU02-Veneza-CE# | C510: 06.626.253/0520-38
A511: 521 | B511: JPA02-MarRondon-RO | C511: 06.626.253/0521-19
A512: 522 | B512: CRS01-CruzeiroSul-AC | C512: 06.626.253/0522-08
A513: 523 | B513: PAF01-PauloAfons-BA# | C513: 06.626.253/0523-80
A514: 524 | B514: SRP01-SJRioPreto-SP | C514: 06.626.253/0524-61
A515: 525 | B515: NAT17-RomualdoGa-RN# | C515: 06.626.253/0525-42
... A600: 612 | B600: CPN05-Taquaral-SP | C600: 06.626.253/0612-90
A601: 613 | B601: ITJ01-Itajuba-MG# | C601: 06.626.253/0613-71 | D601: pedido
A602: 614 | B602: BEL10-SenadoLemos-PA | C602: 06.626.253/0614-52
A603: 615 | B603: BBL01-Barbalha-CE | C603: 06.626.253/0615-33
A604: 616 | B604: FOR65-Paranjana2-CE# | C604: 06.626.253/0616-14
A605: 617 | B605: BEL08-ParqueVerde-PA | C605: 06.626.253/0617-03
A606: 618 | B606: RON02-VilaAurora-MT | C606: 06.626.253/0618-86
A607: 619 | B607: GOI13-SenadCanedo-GO | C607: 06.626.253/0619-67
A608: 620 | B608: BJD01-BeloJardim-PE# | C608: 06.626.253/0620-09
A609: 621 | B609: REC23-Arraial-PE# | C609: 06.626.253/0621-81
A610: 622 | B610: GMA01-Gama-DF | C610: 06.626.253/0622-62
A611: 623 | B611: BSB05-AguasClara-DF# | C611: 06.626.253/0623-43
A612: 624 | B612: CBA08-Mossungue-PR# | C612: 06.626.253/0624-24
...

Sheet Ordens
A1: 604771 | B1: Y600 | C1: 1000 | D1: LOJA 7393 [Troca de Bandeira]
A2: 604772 | B2: Y600 | C2: 1000 | D2: LOJA 7394 [Troca de Bandeira]
A3: 604773 | B3: Y600 | C3: 1000 | D3: LOJA 7399 [Troca de Bandeira]
A4: 604774 | B4: Y600 | C4: 1000 | D4: LOJA 7400 [Troca de Bandeira]
A5: 604775 | B5: Y600 | C5: 1000 | D5: LOJA 7414 [Troca de Bandeira]
A6: 604776 | B6: Y600 | C6: 1000 | D6: LOJA 7416 [Troca de Bandeira]
A7: 604777 | B7: Y600 | C7: 1000 | D7: LOJA 7422 [Troca de Bandeira]
A8: 604779 | B8: Y600 | C8: 1000 | D8: LOJA 7439 [Troca de Bandeira]
A9: 604816 | B9: Y600 | C9: 1000 | D9: LOJA 7049 [Troca de Bandeira]
A10: 604817 | B10: Y600 | C10: 1000 | D10: LOJA 7438 [Troca de Bandeira]
A11: 604818 | B11: Y600 | C11: 1000 | D11: LOJA 7454 [Troca de Bandeira]
A12: 604819 | B12: Y600 | C12: 1000 | D12: LOJA 7462 [Troca de Bandeira]
... A132: 604284 | B132: Y600 | C132: 1000 | D132: FOR196-ScarJer-CE-EF [Troca de Bandeira]

Sheet MATERIAIS
B2: Material Luminária
B4: Modelo Forro 1250
B5: 25913
B7: Modelo Forro 617
B8: 25914
B9: Modelo Sem Forro | C9: MODELO PRETO NA IMAGEM
B10: 26772
B11: Modelo EF75-E2000850 | D11: QUADRADO
B12: 32434
B13: Modelo Balizador
B14: 26726
B15: Modelo Bulbo
B16: 32500
B17: LUMINARIA LED 36W 4450m
B18: 32715
B19: Material Toldo e Persiana
B21: Toldo
B22: 25992
B23: Persiana
B24: 26706
B26: Material CONSTRUÇÃO DE LOJAS
B28: LOJAS NOVAS
B29: 20102
B31: GERENCIAMENTO DE OBRAS
B32: 32432
B34: UTILITIES LOJAS NOVAS
B35: 32433
B37: REFORMA DE LOJA
B38: 20103
B40: COMUNICAÇÃO VISUAL
B41: 20029
B43: RUFO LARGO
B44: 30389
B45: BRAÇO ARTICULADO
B46: 32441
B48: ADEQUAÇÃO
B49: 24755
B51: CHAPA DE FERRO
B52: 32367

Sheet SOLICITAÇÃO DE PRESERVAÇÃO
A1: FILIAL | B1: COORDENADOR | C1: PROJETO | D1: SERVIÇO | E1: ORDEM | F1: DATA ENTRADA | G1: DATA SAÍDA | H1: SOLICITADO? | I1: STATUS | J1: DIAS | K1: HORÁRIO ENTRADA | L1: HORÁRIO SAÍDA | M1: VALOR DIA | N1: VALOR TOTAL
A2: 373 | B2: ADRIANO | C2: REVITALIZA | D2: PRESERVAÇÃO | E2: 605784 | F2: 45884 | G2: 45885 | H2: Sim | I2: =IF(Tabela2[[#This Row],[VALOR TOTAL]]>=1,"Concluído",IF(Tabela2[[#This Row],[SOLICITADO?]]="Sim","Solicitado","")) -> Solicitado | J2: =Tabela2[[#This Row],[DATA SAÍDA]]-Tabela2[[#This Row],[DATA ENTRADA]] -> 1 | K2: 0.875 | L2: 0.29166667 | N2: =Tabela2[[#This Row],[VALOR DIA]]*Tabela2[[#This Row],[DIAS]] -> 0
A3: 63 | B3: ADRIANO | C3: LAUDO DE RISCO | D3: PRESERVAÇÃO | E3: 605753 | F3: 45887 | G3: 45892 | H3: Sim | I3: =IF(Tabela2[[#This Row],[VALOR TOTAL]]>=1,"Concluído",IF(Tabela2[[#This Row],[SOLICITADO?]]="Sim","Solicitado","")) -> Solicitado | J3: =Tabela2[[#This Row],[DATA SAÍDA]]-Tabela2[[#This Row],[DATA ENTRADA]] -> 5 | K3: 0.79166667 | L3: 0.29166667 | N3: =Tabela2[[#This Row],[VALOR DIA]]*Tabela2[[#This Row],[DIAS]] -> 0
A4: 260 | B4: ADRIANO | D4: PRESERVAÇÃO | F4: 45894 | G4: 45895 | H4: Sim | I4: =IF(Tabela2[[#This Row],[VALOR TOTAL]]>=1,"Concluído",IF(Tabela2[[#This Row],[SOLICITADO?]]="Sim","Solicitado","")) -> Solicitado | J4: =Tabela2[[#This Row],[DATA SAÍDA]]-Tabela2[[#This Row],[DATA ENTRADA]] -> 1 | K4: 0.91666667 | L4: 0.29166667 | N4: =Tabela2[[#This Row],[VALOR DIA]]*Tabela2[[#This Row],[DIAS]] -> 0
A5: 260 | B5: ADRIANO | D5: PRESERVAÇÃO | F5: 45903 | G5: 45906 | H5: Sim | I5: =IF(Tabela2[[#This Row],[VALOR TOTAL]]>=1,"Concluído",IF(Tabela2[[#This Row],[SOLICITADO?]]="Sim","Solicitado","")) -> Solicitado | J5: =Tabela2[[#This Row],[DATA SAÍDA]]-Tabela2[[#This Row],[DATA ENTRADA]] -> 3 | K5: 0.95833333 | L5: 0.29166667 | N5: =Tabela2[[#This Row],[VALOR DIA]]*Tabela2[[#This Row],[DIAS]] -> 0
A6: 588 | B6: ADRIANO | D6: PRESERVAÇÃO | F6: 45902 | G6: 45903 | H6: Sim | I6: =IF(Tabela2[[#This Row],[VALOR TOTAL]]>=1,"Concluído",IF(Tabela2[[#This Row],[SOLICITADO?]]="Sim","Solicitado","")) -> Solicitado | J6: =Tabela2[[#This Row],[DATA SAÍDA]]-Tabela2[[#This Row],[DATA ENTRADA]] -> 1 | K6: 0.91666667 | L6: 0.29166667 | N6: =Tabela2[[#This Row],[VALOR DIA]]*Tabela2[[#This Row],[DIAS]] -> 0
A7: 429 | B7: ADRIANO | D7: PRESERVAÇÃO | F7: 45911 | G7: 45913 | H7: Sim | I7: =IF(Tabela2[[#This Row],[VALOR TOTAL]]>=1,"Concluído",IF(Tabela2[[#This Row],[SOLICITADO?]]="Sim","Solicitado","")) -> Solicitado | J7: =Tabela2[[#This Row],[DATA SAÍDA]]-Tabela2[[#This Row],[DATA ENTRADA]] -> 2 | K7: 0.95833333 | L7: 0.25 | N7: =Tabela2[[#This Row],[VALOR DIA]]*Tabela2[[#This Row],[DIAS]] -> 0

Sheet PADRÃO COLUNA CRIAÇÃO RC
A1: ORDEM | B1: MATERIAL | H1: QTDE | I1: PREÇO | M1: DATA | O1: LOJA | P1: RC | Q1: Material Luminária | U1: Descrição | AB1: NCM | AC1: COD MAT
A2: f | B2: 25913 | H2: 66 | I2: 261.37 | M2: 06.10.2025 | O2: 1476 | P2: 10023559 | U2: LED MINI TETRIS MAGNETICO 36W 48V 3000K LUZ DIFUSA CONEX. INFERIOR | AB2: 94051190 | AC2: 32564
A3: f | B3: 25914 | H3: 7 | I3: 207.93 | M3: 06.10.2025 | O3: 1476 | P3: 10023559
A4: f | B4: 32434 | H4: 8 | I4: 264.79 | M4: 06.10.2025 | O4: 1476 | P4: 10023559
A5: f | B5: 25913 | H5: 64 | I5: 261.37 | M5: 06.10.2025 | O5: 1437 | P5: att
A6: f | B6: 25914 | H6: 29 | I6: 207.93 | M6: 06.10.2025 | O6: 1437 | P6: att
A7: f | B7: 32434 | H7: 5 | I7: 264.79 | M7: 06.10.2025 | O7: 1437 | P7: att
A8: f | B8: 25913 | H8: 78 | I8: 238.17 | M8: 06.10.2025 | O8: 1427 | P8: 10023580
A9: f | B9: 25914 | H9: 15 | I9: 189.46 | M9: 06.10.2025 | O9: 1427 | P9: 10023580
A10: f | B10: 25913 | H10: 69 | I10: 240.42 | M10: 06.10.2025 | O10: 1506 | P10: att
A11: f | B11: 25914 | H11: 19 | I11: 191.23 | M11: 06.10.2025 | O11: 1506 | P11: att
A12: f | B12: 32434 | H12: 8 | I12: 243.53 | M12: 06.10.2025 | O12: 1506 | P12: att | Q12: Modelo Forro 1250 | U12: LED PERFIL ALUM. KYOTO SOBR. 3M DIF.FOSCO PT MICRO | AB12: 94059900 | AC12: 32565
A13: f | B13: 25913 | H13: 65 | I13: 240.42 | M13: 06.10.2025 | O13: 1505 | P13: 10023581
A14: f | B14: 25914 | H14: 15 | I14: 191.23 | M14: 06.10.2025 | O14: 1505 | P14: 10023581 | Q14: 25913 | U14: LED FITA FLEX DOUBLE LINE 28,8W/M IP20 24V IRC>90 3000K 256 LEDS/M | AB14: 85395100 | AC14: 32618
A15: f | B15: 32434 | H15: 5 | I15: 226.84 | M15: 06.10.2025 | O15: 1505 | P15: 10023581
A16: f | B16: 25913 | H16: 74 | I16: 277.04 | M16: 06.10.2025 | O16: 1499 | P16: 10023582 | Q16: 32433 | W16: 13437.5 | X16: 1 | AB16: 15.09.2025 | AD16: 382
A17: f | B17: 25914 | H17: 17 | I17: 220.37 | M17: 06.10.2025 | O17: 1499 | P17: 10023582
A18: f | B18: 32434 | H18: 6 | I18: 280.66 | M18: 06.10.2025 | O18: 1499 | P18: 10023582
A19: f | B19: 25913 | H19: 73 | I19: 310.41 | M19: 06.10.2025 | O19: 1401 | P19: 10023583
A20: f | B20: 25914 | H20: 21 | I20: 246.92 | M20: 06.10.2025 | O20: 1401 | P20: 10023583 | Q20: Modelo Forro 617 | U20: LED PERFIL KYOTO SOBR. KIT FIXAC. ACO PEND. | AB20: 94059900 | AC20: 32620
A21: f | B21: 32434 | H21: 4 | I21: 314.48 | M21: 06.10.2025 | O21: 1401 | P21: 10023583 | Q21: 25914 | U21: LED LUMI EMB. PAINEL RETANG. 36W 3000K 320X620 | AB21: 94051190 | AC21: 32621
A22: f | B22: 32434 | H22: 7 | I22: 221.77 | M22: 06.10.2025 | O22: 1427 | Q22: Modelo Sem Forro | R22: MODELO PRETO NA IMAGEM | U22: LED PERFIL ALUM. LONDRES SOBR. 3M DIF.FOSCO BR MICRO | AB22: 94059900 | AC22: 32622
A23: f | B23: 25914 | H23: 3 | I23: 282.46 | M23: 06.10.2025 | O23: 1427 | Q23: 26772 | U23: LED FITA FLEX HIGH 14,4W/M IP20 24V IRC>90 3000K 160 LEDS/M | AB23: 85395100 | AC23: 32623
A24: f | B24: 30333 | H24: 4 | M24: 03.11.2025 | O24: 503 | Q24: Modelo EF75-E2000850 | R24: QUADRADO | U24: LED FONTE TENSAO 100W 24V 90~264VAC IP67 LPV-100-24 | AB24: 85044029 | AC24: 32624
A25: f | B25: 30334 | H25: 4 | M25: 03.11.2025 | O25: 503 | Q25: 32434 | U25: LED LUMI TRACK LIGHT MAG. SUPERIOR 1X LED 10W 48V 3000K 24° BR | AB25: 94051190 | AC25: 32625
A26: f | B26: 30229 | H26: 1 | M26: 03.11.2025 | O26: 503 | Q26: Modelo Balizador | U26: TRILHO MAGNETICO SOBR. SLIM 2M BR | AB26: 94051190 | AC26: 32626
A27: f | B27: 30230 | H27: 1 | M27: 03.11.2025 | O27: 503 | Q27: 26726 | U27: TRILHO MAGNETICO SLIM CONECTOR ALIMENT. EMENDA BR | AB27: 94059900 | AC27: 32627
A28: f | B28: 30100 | H28: 1 | M28: 03.11.2025 | O28: 503 | Q28: Modelo Bulbo | U28: TRILHO MAGNETICO SLIM CONECTOR ALIMENT. C/CABO BR | AB28: 94059900 | AC28: 32628
A29: f | B29: 30101 | H29: 1 | M29: 03.11.2025 | O29: 503 | Q29: 32500 | U29: LED FONTE TENSAO 200W 48V BIVOLT CHAVEADA | AB29: 95044030 | AC29: 32629
A30: f | B30: 30022 | H30: 1 | M30: 03.11.2025 | O30: 503 | Q30: Material Toldo e Persiana
A31: f | B31: 30023 | H31: 1 | M31: 03.11.2025 | O31: 503
A32: f | B32: 20424 | H32: 1 | M32: 03.11.2025 | O32: 503 | Q32: Toldo
A33: f | B33: 25789 | H33: 2 | M33: 03.11.2025 | O33: 503 | Q33: 25992 | R33: 25992
Q34: Persiana | R34: 26706
Q35: 26706
Q37: Material CONSTRUÇÃO DE LOJAS
Q39: LOJAS NOVAS
Q40: 20102
Q42: GERENCIAMENTO DE OBRAS
Q43: 32432
...

Sheet CADASTRO NOVAS UNIDADES CONSUMI
B2: CADASTRO NOVAS UNIDADES CONSUMIDORAS
B3: DT. ABERTURA | C3: CONDIÇÃO | D3: STATUS LOJA | E3: LOJA | F3: ORDEM | G3: FILIAL | H3: COORD | I3: RESULT | J3: TICKET AGUA | K3: DATA TICKET AGUA | L3: STATUS TICKET AGUA | M3: OBS AGUA | N3: TICKET ENERGIA | O3: DATA TICKET ENERGIA | P3: STATUS TICKET ENERGIA | Q3: OBS ENERGIA
B4: =_xlfn.XLOOKUP(E4,[1]Consolidado!$A:$A,[1]Consolidado!$D:$D) -> 45687 | C4: =IF(I4="TICKET CONCLUÍDO", "Concluído", IF(B4 < TODAY(), "Prazo estourado - " & TODAY()-B4 & " dias atrás", IF(TODAY()+30 < B4, "No prazo - faltam " & B4-TODAY() & " dias", IF(AND(B4-TODAY()<=29, B4-TODAY()>7), "Solicitar dados - faltam " & B4-TODAY() & " dias", IF(B4-TODAY()<=7, "Resolicitar - faltam " & B4-TODAY() & " dias", "Verificar") ) ) ) ) -> Concluído | D4: =_xlfn.XLOOKUP(E4,[1]Consolidado!$A:$A,[1]Consolidado!$AN:$AN) -> 0 | E4: OEI01-Oeiras-PI | F4: =_xlfn.XLOOKUP(E4,'SOLICITAÇÃO DE PAGAMENTO'!C:C,'SOLICITAÇÃO DE PAGAMENTO'!M:M) -> 602883 | G4: =_xlfn.XLOOKUP(E4,'SOLICITAÇÃO DE PAGAMENTO'!C:C,'SOLICITAÇÃO DE PAGAMENTO'!B:B) -> 1440 | H4: =_xlfn.XLOOKUP(G4,'SOLICITAÇÃO DE PAGAMENTO'!B:B,'SOLICITAÇÃO DE PAGAMENTO'!E:E) -> ANDRE | I4: =IF(AND(L4="RESPONSABILIDADE CSC",P4="RESPONSABILIDADE CSC"),"TICKET CONCLUÍDO", "PENDENTE") -> TICKET CONCLUÍDO | J4: 1118416 | K4: 45691 | L4: RESPONSABILIDADE CSC | M4: FATURA EM ABERTO PAGA | N4: 1118394 | O4: 45691 | P4: RESPONSABILIDADE CSC | Q4: FATURA EM ABERTO PAGA
B5: =_xlfn.XLOOKUP(E5,[1]Consolidado!$A:$A,[1]Consolidado!$D:$D) -> 45670 | C5: =IF(I5="TICKET CONCLUÍDO", "Concluído", IF(B5 < TODAY(), "Prazo estourado - " & TODAY()-B5 & " dias atrás", IF(TODAY()+30 < B5, "No prazo - faltam " & B5-TODAY() & " dias", IF(AND(B5-TODAY()<=29, B5-TODAY()>7), "Solicitar dados - faltam " & B5-TODAY() & " dias", IF(B5-TODAY()<=7, "Resolicitar - faltam " & B5-TODAY() & " dias", "Verificar") ) ) ) ) -> Concluído | D5: =_xlfn.XLOOKUP(E5,[1]Consolidado!$A:$A,[1]Consolidado!$AN:$AN) -> 0 | E5: FOR192-AlCraveiro-CE | F5: =_xlfn.XLOOKUP(E5,'SOLICITAÇÃO DE PAGAMENTO'!C:C,'SOLICITAÇÃO DE PAGAMENTO'!M:M) -> 603708 | G5: 1479 | H5: =_xlfn.XLOOKUP(G5,'SOLICITAÇÃO DE PAGAMENTO'!B:B,'SOLICITAÇÃO DE PAGAMENTO'!E:E) -> JORDANA | I5: TICKET CONCLUÍDO | L5: COBRANCA VIA CONDOMINIO DO SHOPPING | N5: 1118352 | O5: 45691 | P5: RESPONSABILIDADE CSC
B6: =_xlfn.XLOOKUP(E6,[1]Consolidado!$A:$A,[1]Consolidado!$D:$D) -> 45688 | C6: =IF(I6="TICKET CONCLUÍDO", "Concluído", IF(B6 < TODAY(), "Prazo estourado - " & TODAY()-B6 & " dias atrás", IF(TODAY()+30 < B6, "No prazo - faltam " & B6-TODAY() & " dias", IF(AND(B6-TODAY()<=29, B6-TODAY()>7), "Solicitar dados - faltam " & B6-TODAY() & " dias", IF(B6-TODAY()<=7, "Resolicitar - faltam " & B6-TODAY() & " dias", "Verificar") ) ) ) ) -> Concluído | D6: =_xlfn.XLOOKUP(E6,[1]Consolidado!$A:$A,[1]Consolidado!$AN:$AN) -> 0 | E6: PRB03-Liberdade-PA | F6: =_xlfn.XLOOKUP(E6,'SOLICITAÇÃO DE PAGAMENTO'!C:C,'SOLICITAÇÃO DE PAGAMENTO'!M:M) -> 603682 | G6: 1461 | H6: =_xlfn.XLOOKUP(G6,'SOLICITAÇÃO DE PAGAMENTO'!B:B,'SOLICITAÇÃO DE PAGAMENTO'!E:E) -> HENRIQUE | I6: =IF(AND(L6="RESPONSABILIDADE CSC",P6="RESPONSABILIDADE CSC"),"TICKET CONCLUÍDO", "PENDENTE") -> TICKET CONCLUÍDO | J6: 1118464 | K6: 45691 | L6: RESPONSABILIDADE CSC | N6: 1288763 | O6: 45716 | P6: RESPONSABILIDADE CSC
B7: =_xlfn.XLOOKUP(E7,[1]Consolidado!$A:$A,[1]Consolidado!$D:$D) -> 45684 | C7: =IF(I7="TICKET CONCLUÍDO", "Concluído", IF(B7 < TODAY(), "Prazo estourado - " & TODAY()-B7 & " dias atrás", IF(TODAY()+30 < B7, "No prazo - faltam " & B7-TODAY() & " dias", IF(AND(B7-TODAY()<=29, B7-TODAY()>7), "Solicitar dados - faltam " & B7-TODAY() & " dias", IF(B7-TODAY()<=7, "Resolicitar - faltam " & B7-TODAY() & " dias", "Verificar") ) ) ) ) -> Concluído | D7: =_xlfn.XLOOKUP(E7,[1]Consolidado!$A:$A,[1]Consolidado!$AN:$AN) -> 0 | E7: FOR191-15Novembro-CE | F7: =_xlfn.XLOOKUP(E7,'SOLICITAÇÃO DE PAGAMENTO'!C:C,'SOLICITAÇÃO DE PAGAMENTO'!M:M) -> 603700 | G7: =_xlfn.XLOOKUP(E7,'SOLICITAÇÃO DE PAGAMENTO'!C:C,'SOLICITAÇÃO DE PAGAMENTO'!B:B) -> 1484 | H7: =_xlfn.XLOOKUP(G7,'SOLICITAÇÃO DE PAGAMENTO'!B:B,'SOLICITAÇÃO DE PAGAMENTO'!E:E) -> JORDANA | I7: =IF(AND(L7="RESPONSABILIDADE CSC",P7="RESPONSABILIDADE CSC"),"TICKET CONCLUÍDO", "PENDENTE") -> TICKET CONCLUÍDO | J7: 1118329 | K7: 45691 | L7: RESPONSABILIDADE CSC | N7: 1338816/ 2124182 | O7: 45845 | P7: RESPONSABILIDADE CSC
B8: =_xlfn.XLOOKUP(E8,[1]Consolidado!$A:$A,[1]Consolidado!$D:$D) -> 45701 | C8: =IF(I8="TICKET CONCLUÍDO", "Concluído", IF(B8 < TODAY(), "Prazo estourado - " & TODAY()-B8 & " dias atrás", IF(TODAY()+30 < B8, "No prazo - faltam " & B8-TODAY() & " dias", IF(AND(B8-TODAY()<=29, B8-TODAY()>7), "Solicitar dados - faltam " & B8-TODAY() & " dias", IF(B8-TODAY()<=7, "Resolicitar - faltam " & B8-TODAY() & " dias", "Verificar") ) ) ) ) -> Concluído | D8: =_xlfn.XLOOKUP(E8,[1]Consolidado!$A:$A,[1]Consolidado!$AN:$AN) -> 0 | E8: REC74-LuizNunes-PE | F8: =_xlfn.XLOOKUP(E8,'SOLICITAÇÃO DE PAGAMENTO'!C:C,'SOLICITAÇÃO DE PAGAMENTO'!M:M) -> 603125 | G8: =_xlfn.XLOOKUP(E8,'SOLICITAÇÃO DE PAGAMENTO'!C:C,'SOLICITAÇÃO DE PAGAMENTO'!B:B) -> 1372 | H8: =_xlfn.XLOOKUP(G8,'SOLICITAÇÃO DE PAGAMENTO'!B:B,'SOLICITAÇÃO DE PAGAMENTO'!E:E) -> JORDANA | I8: =IF(AND(L8="RESPONSABILIDADE CSC",P8="RESPONSABILIDADE CSC"),"TICKET CONCLUÍDO", "PENDENTE") -> TICKET CONCLUÍDO | J8: 1338630 | K8: 45726 | L8: RESPONSABILIDADE CSC | N8: 1338590 | O8: 45726 | P8: RESPONSABILIDADE CSC
B9: =_xlfn.XLOOKUP(E9,[1]Consolidado!$A:$A,[1]Consolidado!$D:$D) -> 45719 | C9: =IF(I9="TICKET CONCLUÍDO", "Concluído", IF(B9 < TODAY(), "Prazo estourado - " & TODAY()-B9 & " dias atrás", IF(TODAY()+30 < B9, "No prazo - faltam " & B9-TODAY() & " dias", IF(AND(B9-TODAY()<=29, B9-TODAY()>7), "Solicitar dados - faltam " & B9-TODAY() & " dias", IF(B9-TODAY()<=7, "Resolicitar - faltam " & B9-TODAY() & " dias", "Verificar") ) ) ) ) -> Concluído | D9: =_xlfn.XLOOKUP(E9,[1]Consolidado!$A:$A,[1]Consolidado!$AN:$AN) -> 0 | E9: REC72-AntFalcao-PE | F9: =_xlfn.XLOOKUP(E9,'SOLICITAÇÃO DE PAGAMENTO'!C:C,'SOLICITAÇÃO DE PAGAMENTO'!M:M) -> 603254 | G9: =_xlfn.XLOOKUP(E9,'SOLICITAÇÃO DE PAGAMENTO'!C:C,'SOLICITAÇÃO DE PAGAMENTO'!B:B) -> 1432 | H9: =_xlfn.XLOOKUP(G9,'SOLICITAÇÃO DE PAGAMENTO'!B:B,'SOLICITAÇÃO DE PAGAMENTO'!E:E) -> JORDANA | I9: =IF(AND(L9="RESPONSABILIDADE CSC",P9="RESPONSABILIDADE CSC"),"TICKET CONCLUÍDO", "PENDENTE") -> TICKET CONCLUÍDO | J9: 1338879 | K9: 45726 | L9: RESPONSABILIDADE CSC | N9: 1338858 | O9: 45726 | P9: RESPONSABILIDADE CSC
B10: =_xlfn.XLOOKUP(E10,[1]Consolidado!$A:$A,[1]Consolidado!$D:$D) -> 45726 | C10: =IF(I10="TICKET CONCLUÍDO", "Concluído", IF(B10 < TODAY(), "Prazo estourado - " & TODAY()-B10 & " dias atrás", IF(TODAY()+30 < B10, "No prazo - faltam " & B10-TODAY() & " dias", IF(AND(B10-TODAY()<=29, B10-TODAY()>7), "Solicitar dados - faltam " & B10-TODAY() & " dias", IF(B10-TODAY()<=7, "Resolicitar - faltam " & B10-TODAY() & " dias", "Verificar") ) ) ) ) -> Concluído | D10: =_xlfn.XLOOKUP(E10,[1]Consolidado!$A:$A,[1]Consolidado!$AN:$AN) -> 0 | E10: BJS02-ManuelLeite-CE | F10: 603999 | G10: 1481 | H10: =_xlfn.XLOOKUP(G10,'SOLICITAÇÃO DE PAGAMENTO'!B:B,'SOLICITAÇÃO DE PAGAMENTO'!E:E) -> JORDANA | I10: =IF(AND(L10="RESPONSABILIDADE CSC",P10="RESPONSABILIDADE CSC"),"TICKET CONCLUÍDO", "PENDENTE") -> TICKET CONCLUÍDO | J10: 1381149 | L10: RESPONSABILIDADE CSC | M10: NECESSISDA DE ALTERAÇÃO DE TITULARIDADE | N10: 1381113 | P10: RESPONSABILIDADE CSC
B11: =_xlfn.XLOOKUP(E11,[1]Consolidado!$A:$A,[1]Consolidado!$D:$D) -> 45763 | C11: =IF(I11="TICKET CONCLUÍDO", "Concluído", IF(B11 < TODAY(), "Prazo estourado - " & TODAY()-B11 & " dias atrás", IF(TODAY()+30 < B11, "No prazo - faltam " & B11-TODAY() & " dias", IF(AND(B11-TODAY()<=29, B11-TODAY()>7), "Solicitar dados - faltam " & B11-TODAY() & " dias", IF(B11-TODAY()<=7, "Resolicitar - faltam " & B11-TODAY() & " dias", "Verificar") ) ) ) ) -> Concluído | D11: =_xlfn.XLOOKUP(E11,[1]Consolidado!$A:$A,[1]Consolidado!$AN:$AN) -> 0 | E11: RBR13-VilaIvonete-AC | F11: =_xlfn.XLOOKUP(E11,'SOLICITAÇÃO DE PAGAMENTO'!C:C,'SOLICITAÇÃO DE PAGAMENTO'!M:M) -> 603787 | G11: =_xlfn.XLOOKUP(E11,'SOLICITAÇÃO DE PAGAMENTO'!C:C,'SOLICITAÇÃO DE PAGAMENTO'!B:B) -> 1446 | H11: =_xlfn.XLOOKUP(G11,'SOLICITAÇÃO DE PAGAMENTO'!B:B,'SOLICITAÇÃO DE PAGAMENTO'!E:E) -> HENRIQUE | I11: =IF(AND(L11="RESPONSABILIDADE CSC",P11="RESPONSABILIDADE CSC"),"TICKET CONCLUÍDO", "PENDENTE") -> TICKET CONCLUÍDO | J11: 1664569 | K11: 45777 | L11: RESPONSABILIDADE CSC | M11: FATURA EM ABERTO PAGA | N11: 1664554 | O11: 45777 | P11: RESPONSABILIDADE CSC
B12: =_xlfn.XLOOKUP(E12,[1]Consolidado!$A:$A,[1]Consolidado!$D:$D) -> 45761 | C12: =IF(I12="TICKET CONCLUÍDO", "Concluído", IF(B12 < TODAY(), "Prazo estourado - " & TODAY()-B12 & " dias atrás", IF(TODAY()+30 < B12, "No prazo - faltam " & B12-TODAY() & " dias", IF(AND(B12-TODAY()<=29, B12-TODAY()>7), "Solicitar dados - faltam " & B12-TODAY() & " dias", IF(B12-TODAY()<=7, "Resolicitar - faltam " & B12-TODAY() & " dias", "Verificar") ) ) ) ) -> Concluído | D12: =_xlfn.XLOOKUP(E12,[1]Consolidado!$A:$A,[1]Consolidado!$AN:$AN) -> 0 | E12: MAC26-Aldebaran-AL | F12: =_xlfn.XLOOKUP(E12,'SOLICITAÇÃO DE PAGAMENTO'!C:C,'SOLICITAÇÃO DE PAGAMENTO'!M:M) -> 603265 | G12: =_xlfn.XLOOKUP(E12,'SOLICITAÇÃO DE PAGAMENTO'!C:C,'SOLICITAÇÃO DE PAGAMENTO'!B:B) -> 1381 | H12: =_xlfn.XLOOKUP(G12,'SOLICITAÇÃO DE PAGAMENTO'!B:B,'SOLICITAÇÃO DE PAGAMENTO'!E:E) -> ANDRE | I12: TICKET CONCLUÍDO | L12: AGUARDANDO INSTALAÇÃO DE POÇO ARTESIANO | N12: 1721945 | O12: 45785 | P12: =IF(N12="","AGUARDANDO DADOS","RESPONSABILIDADE CSC") -> RESPONSABILIDADE CSC
B13: =_xlfn.XLOOKUP(E13,[1]Consolidado!$A:$A,[1]Consolidado!$D:$D) -> 45860 | C13: =IF(I13="TICKET CONCLUÍDO", "Concluído", IF(B13 < TODAY(), "Prazo estourado - " & TODAY()-B13 & " dias atrás", IF(TODAY()+30 < B13, "No prazo - faltam " & B13-TODAY() & " dias", IF(AND(B13-TODAY()<=29, B13-TODAY()>7), "Solicitar dados - faltam " & B13-TODAY() & " dias", IF(B13-TODAY()<=7, "Resolicitar - faltam " & B13-TODAY() & " dias", "Verificar") ) ) ) ) -> Concluído | D13: =_xlfn.XLOOKUP(E13,[1]Consolidado!$A:$A,[1]Consolidado!$AN:$AN) -> 0 | E13: JPE50-FcoLeocadio-PB | F13: =_xlfn.XLOOKUP(E13,'SOLICITAÇÃO DE PAGAMENTO'!C:C,'SOLICITAÇÃO DE PAGAMENTO'!M:M) -> 604010 | G13: =_xlfn.XLOOKUP(E13,'SOLICITAÇÃO DE PAGAMENTO'!C:C,'SOLICITAÇÃO DE PAGAMENTO'!B:B) -> 1464 | H13: =_xlfn.XLOOKUP(G13,'SOLICITAÇÃO DE PAGAMENTO'!B:B,'SOLICITAÇÃO DE PAGAMENTO'!E:E) -> ANDRE | I13: =IF(AND(L13="RESPONSABILIDADE CSC",P13="RESPONSABILIDADE CSC"),"TICKET CONCLUÍDO", "PENDENTE") -> TICKET CONCLUÍDO | J13: 1566305 | K13: 45761 | L13: RESPONSABILIDADE CSC | N13: 1565928 | O13: 45761 | P13: RESPONSABILIDADE CSC
B14: =_xlfn.XLOOKUP(E14,[1]Consolidado!$A:$A,[1]Consolidado!$D:$D) -> 45797 | C14: =IF(I14="TICKET CONCLUÍDO", "Concluído", IF(B14 < TODAY(), "Prazo estourado - " & TODAY()-B14 & " dias atrás", IF(TODAY()+30 < B14, "No prazo - faltam " & B14-TODAY() & " dias", IF(AND(B14-TODAY()<=29, B14-TODAY()>7), "Solicitar dados - faltam " & B14-TODAY() & " dias", IF(B14-TODAY()<=7, "Resolicitar - faltam " & B14-TODAY() & " dias", "Verificar") ) ) ) ) -> Concluído | D14: =_xlfn.XLOOKUP(E14,[1]Consolidado!$A:$A,[1]Consolidado!$AN:$AN) -> 0 | E14: SAL64-ShBahia-BA | F14: 605289 | G14: 845 | H14: =_xlfn.XLOOKUP(G14,'SOLICITAÇÃO DE PAGAMENTO'!B:B,'SOLICITAÇÃO DE PAGAMENTO'!E:E) -> ANDRE | I14: =IF(AND(L14="RESPONSABILIDADE CSC",P14="RESPONSABILIDADE CSC"),"TICKET CONCLUÍDO", "PENDENTE") -> TICKET CONCLUÍDO | L14: RESPONSABILIDADE CSC | P14: RESPONSABILIDADE CSC
B15: =_xlfn.XLOOKUP(E15,[1]Consolidado!$A:$A,[1]Consolidado!$D:$D) -> 45813 | C15: =IF(I15="TICKET CONCLUÍDO", "Concluído", IF(B15 < TODAY(), "Prazo estourado - " & TODAY()-B15 & " dias atrás", IF(TODAY()+30 < B15, "No prazo - faltam " & B15-TODAY() & " dias", IF(AND(B15-TODAY()<=29, B15-TODAY()>7), "Solicitar dados - faltam " & B15-TODAY() & " dias", IF(B15-TODAY()<=7, "Resolicitar - faltam " & B15-TODAY() & " dias", "Verificar") ) ) ) ) -> Concluído | D15: =_xlfn.XLOOKUP(E15,[1]Consolidado!$A:$A,[1]Consolidado!$AN:$AN) -> 0 | E15: AGU01-AguaBranca-PI | F15: 604407 | G15: 1486 | H15: =_xlfn.XLOOKUP(G15,'SOLICITAÇÃO DE PAGAMENTO'!B:B,'SOLICITAÇÃO DE PAGAMENTO'!E:E) -> ANDRE | I15: =IF(AND(L15="RESPONSABILIDADE CSC",P15="RESPONSABILIDADE CSC"),"TICKET CONCLUÍDO", "PENDENTE") -> TICKET CONCLUÍDO | J15: 1825691 | K15: 45800 | L15: =IF(J15="","AGUARDANDO DADOS","RESPONSABILIDADE CSC") -> RESPONSABILIDADE CSC | M15: FATURA EM ABERTO PAGA | N15: 1825579 | O15: 45800 | P15: =IF(N15="","AGUARDANDO DADOS","RESPONSABILIDADE CSC") -> RESPONSABILIDADE CSC | Q15: FATURA EM ABERTO PAGA
B16: =_xlfn.XLOOKUP(E16,[1]Consolidado!$A:$A,[1]Consolidado!$D:$D) -> 45780 | C16: =IF(I16="TICKET CONCLUÍDO", "Concluído", IF(B16 < TODAY(), "Prazo estourado - " & TODAY()-B16 & " dias atrás", IF(TODAY()+30 < B16, "No prazo - faltam " & B16-TODAY() & " dias", IF(AND(B16-TODAY()<=29, B16-TODAY()>7), "Solicitar dados - faltam " & B16-TODAY() & " dias", IF(B16-TODAY()<=7, "Resolicitar - faltam " & B16-TODAY() & " dias", "Verificar") ) ) ) ) -> Concluído | D16: =_xlfn.XLOOKUP(E16,[1]Consolidado!$A:$A,[1]Consolidado!$AN:$AN) -> 0 | E16: TER31-CasteloPiaui-PI | F16: =_xlfn.XLOOKUP(E16,'SOLICITAÇÃO DE PAGAMENTO'!C:C,'SOLICITAÇÃO DE PAGAMENTO'!M:M) -> 603846 | G16: =_xlfn.XLOOKUP(E16,'SOLICITAÇÃO DE PAGAMENTO'!C:C,'SOLICITAÇÃO DE PAGAMENTO'!B:B) -> 1473 | H16: =_xlfn.XLOOKUP(G16,'SOLICITAÇÃO DE PAGAMENTO'!B:B,'SOLICITAÇÃO DE PAGAMENTO'!E:E) -> HENRIQUE | I16: =IF(AND(L16="RESPONSABILIDADE CSC",P16="RESPONSABILIDADE CSC"),"TICKET CONCLUÍDO", "PENDENTE") -> TICKET CONCLUÍDO | J16: 1679019 | K16: 45779 | L16: RESPONSABILIDADE CSC | N16: 1679405 | O16: 45779 | P16: RESPONSABILIDADE CSC
B17: =_xlfn.XLOOKUP(E17,[1]Consolidado!$A:$A,[1]Consolidado!$D:$D) -> 45796 | C17: =IF(I17="TICKET CONCLUÍDO", "Concluído", IF(B17 < TODAY(), "Prazo estourado - " & TODAY()-B17 & " dias atrás", IF(TODAY()+30 < B17, "No prazo - faltam " & B17-TODAY() & " dias", IF(AND(B17-TODAY()<=29, B17-TODAY()>7), "Solicitar dados - faltam " & B17-TODAY() & " dias", IF(B17-TODAY()<=7, "Resolicitar - faltam " & B17-TODAY() & " dias", "Verificar") ) ) ) ) -> Concluído | D17: =_xlfn.XLOOKUP(E17,[1]Consolidado!$A:$A,[1]Consolidado!$AN:$AN) -> 0 | E17: CGD23-TrêsBarras-MS | F17: =_xlfn.XLOOKUP(E17,'SOLICITAÇÃO DE PAGAMENTO'!C:C,'SOLICITAÇÃO DE PAGAMENTO'!M:M) -> 603320 | G17: =_xlfn.XLOOKUP(E17,'SOLICITAÇÃO DE PAGAMENTO'!C:C,'SOLICITAÇÃO DE PAGAMENTO'!B:B) -> 1483 | H17: =_xlfn.XLOOKUP(G17,'SOLICITAÇÃO DE PAGAMENTO'!B:B,'SOLICITAÇÃO DE PAGAMENTO'!E:E) -> ANDRE | I17: =IF(AND(L17="RESPONSABILIDADE CSC",P17="RESPONSABILIDADE CSC"),"TICKET CONCLUÍDO", "PENDENTE") -> TICKET CONCLUÍDO | J17: 1721816 | K17: 45785 | L17: =IF(J17="","AGUARDANDO DADOS","RESPONSABILIDADE CSC") -> RESPONSABILIDADE CSC | M17: FATURA EM ABERTO VENC 07/05/2025 (OBRAS) | N17: 1681574 | O17: 45779 | P17: =IF(N17="","AGUARDANDO DADOS","RESPONSABILIDADE CSC") -> RESPONSABILIDADE CSC | Q17: FATURA EM ABERTO PAGA
B18: =_xlfn.XLOOKUP(E18,[1]Consolidado!$A:$A,[1]Consolidado!$D:$D) -> 45796 | C18: =IF(I18="TICKET CONCLUÍDO", "Concluído", IF(B18 < TODAY(), "Prazo estourado - " & TODAY()-B18 & " dias atrás", IF(TODAY()+30 < B18, "No prazo - faltam " & B18-TODAY() & " dias", IF(AND(B18-TODAY()<=29, B18-TODAY()>7), "Solicitar dados - faltam " & B18-TODAY() & " dias", IF(B18-TODAY()<=7, "Resolicitar - faltam " & B18-TODAY() & " dias", "Verificar") ) ) ) ) -> Concluído | D18: =_xlfn.XLOOKUP(E18,[1]Consolidado!$A:$A,[1]Consolidado!$AN:$AN) -> 0 | E18: VAR06-JoaoPonce-MT | F18: =_xlfn.XLOOKUP(E18,'SOLICITAÇÃO DE PAGAMENTO'!C:C,'SOLICITAÇÃO DE PAGAMENTO'!M:M) -> 603908 | G18: =_xlfn.XLOOKUP(E18,'SOLICITAÇÃO DE PAGAMENTO'!C:C,'SOLICITAÇÃO DE PAGAMENTO'!B:B) -> 1455 | H18: =_xlfn.XLOOKUP(G18,'SOLICITAÇÃO DE PAGAMENTO'!B:B,'SOLICITAÇÃO DE PAGAMENTO'!E:E) -> JORDANA | I18: =IF(AND(L18="RESPONSABILIDADE CSC",P18="RESPONSABILIDADE CSC"),"TICKET CONCLUÍDO", "PENDENTE") -> TICKET CONCLUÍDO | J18: 1721727 | K18: 45785 | L18: =IF(J18="","AGUARDANDO DADOS","RESPONSABILIDADE CSC") -> RESPONSABILIDADE CSC | M18: FATURA EM ABERTO PAGA | N18: 1721700 | O18: 45785 | P18: =IF(N18="","AGUARDANDO DADOS","RESPONSABILIDADE CSC") -> RESPONSABILIDADE CSC
B19: =_xlfn.XLOOKUP(E19,[1]Consolidado!$A:$A,[1]Consolidado!$D:$D) -> 45810 | C19: =IF(I19="TICKET CONCLUÍDO", "Concluído", IF(B19 < TODAY(), "Prazo estourado - " & TODAY()-B19 & " dias atrás", IF(TODAY()+30 < B19, "No prazo - faltam " & B19-TODAY() & " dias", IF(AND(B19-TODAY()<=29, B19-TODAY()>7), "Solicitar dados - faltam " & B19-TODAY() & " dias", IF(B19-TODAY()<=7, "Resolicitar - faltam " & B19-TODAY() & " dias", "Verificar") ) ) ) ) -> Concluído | D19: =_xlfn.XLOOKUP(E19,[1]Consolidado!$A:$A,[1]Consolidado!$AN:$AN) -> 0 | E19: CRA05-CelAntLuiz-CE | F19: =_xlfn.XLOOKUP(E19,'SOLICITAÇÃO DE PAGAMENTO'!C:C,'SOLICITAÇÃO DE PAGAMENTO'!M:M) -> 603914 | G19: =_xlfn.XLOOKUP(E19,'SOLICITAÇÃO DE PAGAMENTO'!C:C,'SOLICITAÇÃO DE PAGAMENTO'!B:B) -> 1480 | H19: =_xlfn.XLOOKUP(G19,'SOLICITAÇÃO DE PAGAMENTO'!B:B,'SOLICITAÇÃO DE PAGAMENTO'!E:E) -> JORDANA | I19: =IF(AND(L19="RESPONSABILIDADE CSC",P19="RESPONSABILIDADE CSC"),"TICKET CONCLUÍDO", "PENDENTE") -> TICKET CONCLUÍDO | J19: 1824402 | K19: 45800 | L19: =IF(J19="","AGUARDANDO DADOS","RESPONSABILIDADE CSC") -> RESPONSABILIDADE CSC | N19: 2344147 | O19: 45881 | P19: =IF(N19="","AGUARDANDO DADOS","RESPONSABILIDADE CSC") -> RESPONSABILIDADE CSC | Q19: aguardando troca de titularidade, entender o motivo do atraso
B20: =_xlfn.XLOOKUP(E20,[1]Consolidado!$A:$A,[1]Consolidado!$D:$D) -> 45848 | C20: =IF(I20="TICKET CONCLUÍDO", "Concluído", IF(B20 < TODAY(), "Prazo estourado - " & TODAY()-B20 & " dias atrás", IF(TODAY()+30 < B20, "No prazo - faltam " & B20-TODAY() & " dias", IF(AND(B20-TODAY()<=29, B20-TODAY()>7), "Solicitar dados - faltam " & B20-TODAY() & " dias", IF(B20-TODAY()<=7, "Resolicitar - faltam " & B20-TODAY() & " dias", "Verificar") ) ) ) ) -> Concluído | D20: =_xlfn.XLOOKUP(E20,[1]Consolidado!$A:$A,[1]Consolidado!$AN:$AN) -> 0 | E20: TER32-15deNov-PI | F20: =_xlfn.XLOOKUP(E20,'SOLICITAÇÃO DE PAGAMENTO'!C:C,'SOLICITAÇÃO DE PAGAMENTO'!M:M) -> 604002 | G20: =_xlfn.XLOOKUP(E20,'SOLICITAÇÃO DE PAGAMENTO'!C:C,'SOLICITAÇÃO DE PAGAMENTO'!B:B) -> 1475 | H20: =_xlfn.XLOOKUP(G20,'SOLICITAÇÃO DE PAGAMENTO'!B:B,'SOLICITAÇÃO DE PAGAMENTO'!E:E) -> ANDRE | I20: =IF(AND(L20="RESPONSABILIDADE CSC",P20="RESPONSABILIDADE CSC"),"TICKET CONCLUÍDO", "PENDENTE") -> TICKET CONCLUÍDO | J20: 2080458 | K20: 45839 | L20: =IF(J20="","AGUARDANDO DADOS","RESPONSABILIDADE CSC") -> RESPONSABILIDADE CSC | N20: 2080508 | O20: 45839 | P20: =IF(N20="","AGUARDANDO DADOS","RESPONSABILIDADE CSC") -> RESPONSABILIDADE CSC
B21: =_xlfn.XLOOKUP(E21,[1]Consolidado!$A:$A,[1]Consolidado!$D:$D) -> 45835 | C21: =IF(I21="TICKET CONCLUÍDO", "Concluído", IF(B21 < TODAY(), "Prazo estourado - " & TODAY()-B21 & " dias atrás", IF(TODAY()+30 < B21, "No prazo - faltam " & B21-TODAY() & " dias", IF(AND(B21-TODAY()<=29, B21-TODAY()>7), "Solicitar dados - faltam " & B21-TODAY() & " dias", IF(B21-TODAY()<=7, "Resolicitar - faltam " & B21-TODAY() & " dias", "Verificar") ) ) ) ) -> Concluído | D21: =_xlfn.XLOOKUP(E21,[1]Consolidado!$A:$A,[1]Consolidado!$AN:$AN) -> 0 | E21: AQU03-BeachPark-CE | F21: =_xlfn.XLOOKUP(E21,'SOLICITAÇÃO DE PAGAMENTO'!C:C,'SOLICITAÇÃO DE PAGAMENTO'!M:M) -> 605638 | G21: =_xlfn.XLOOKUP(E21,'SOLICITAÇÃO DE PAGAMENTO'!C:C,'SOLICITAÇÃO DE PAGAMENTO'!B:B) -> 1485 | H21: =_xlfn.XLOOKUP(G21,'SOLICITAÇÃO DE PAGAMENTO'!B:B,'SOLICITAÇÃO DE PAGAMENTO'!E:E) -> JORDANA | I21: =IF(AND(L21="RESPONSABILIDADE CSC",P21="RESPONSABILIDADE CSC"),"TICKET CONCLUÍDO", "PENDENTE") -> TICKET CONCLUÍDO | L21: RESPONSABILIDADE CSC | P21: RESPONSABILIDADE CSC
B22: =_xlfn.XLOOKUP(E22,[1]Consolidado!$A:$A,[1]Consolidado!$D:$D) -> 45843 | C22: =IF(I22="TICKET CONCLUÍDO", "Concluído", IF(B22 < TODAY(), "Prazo estourado - " & TODAY()-B22 & " dias atrás", IF(TODAY()+30 < B22, "No prazo - faltam " & B22-TODAY() & " dias", IF(AND(B22-TODAY()<=29, B22-TODAY()>7), "Solicitar dados - faltam " & B22-TODAY() & " dias", IF(B22-TODAY()<=7, "Resolicitar - faltam " & B22-TODAY() & " dias", "Verificar") ) ) ) ) -> Concluído | D22: =_xlfn.XLOOKUP(E22,[1]Consolidado!$A:$A,[1]Consolidado!$AN:$AN) -> 0 | E22: CRU14-LeãoDourado-PE | F22: 603049 | G22: 1369 | H22: JORDANA | I22: =IF(AND(L22="RESPONSABILIDADE CSC",P22="RESPONSABILIDADE CSC"),"TICKET CONCLUÍDO", "PENDENTE") -> TICKET CONCLUÍDO | J22: 2069000 | K22: 45838 | L22: =IF(J22="","AGUARDANDO DADOS","RESPONSABILIDADE CSC") -> RESPONSABILIDADE CSC | N22: 2211965 | O22: 45859 | P22: =IF(N22="","AGUARDANDO DADOS","RESPONSABILIDADE CSC") -> RESPONSABILIDADE CSC | Q22: [16:41, 11/07/2025] Carina Alvo K: a concessionária, por questões sistêmicas, vai precisar alterar a conta contrato, inativando a existente (somente no sistema, e não fisicamente). Sendo assim, o pedido de troca da titularidade anterior foi cancelado. E uma solicitação de nova Conta Contrato será protocolada pelo Sílvio. [16:43, 11/07/2025] Carina Alvo K: Ele disse que esse novo cadastro será feito até sexta feira que vem, 18/07
B23: =_xlfn.XLOOKUP(E23,[1]Consolidado!$A:$A,[1]Consolidado!$D:$D) -> 45896 | C23: =IF(I23="TICKET CONCLUÍDO", "Concluído", IF(B23 < TODAY(), "Prazo estourado - " & TODAY()-B23 & " dias atrás", IF(TODAY()+30 < B23, "No prazo - faltam " & B23-TODAY() & " dias", IF(AND(B23-TODAY()<=29, B23-TODAY()>7), "Solicitar dados - faltam " & B23-TODAY() & " dias", IF(B23-TODAY()<=7, "Resolicitar - faltam " & B23-TODAY() & " dias", "Verificar") ) ) ) ) -> Concluído | D23: =_xlfn.XLOOKUP(E23,[1]Consolidado!$A:$A,[1]Consolidado!$AN:$AN) -> 0 | E23: SLU79-Cajazeiras-MA | F23: =_xlfn.XLOOKUP(E23,'SOLICITAÇÃO DE PAGAMENTO'!C:C,'SOLICITAÇÃO DE PAGAMENTO'!M:M) -> 603464 | G23: =_xlfn.XLOOKUP(E23,'SOLICITAÇÃO DE PAGAMENTO'!C:C,'SOLICITAÇÃO DE PAGAMENTO'!B:B,"") -> 1498 | H23: HENRIQUE | I23: =IF(AND(L23="RESPONSABILIDADE CSC",P23="RESPONSABILIDADE CSC"),"TICKET CONCLUÍDO", "PENDENTE") -> TICKET CONCLUÍDO | J23: 2190263 | K23: 45855 | L23: =IF(J23="","AGUARDANDO DADOS","RESPONSABILIDADE CSC") -> RESPONSABILIDADE CSC | M23: solicitei dados cadastrais aguardando | N23: 2190230 | O23: 45855 | P23: =IF(N23="","AGUARDANDO DADOS","RESPONSABILIDADE CSC") -> RESPONSABILIDADE CSC | Q23: solicitei dados cadastrais aguardando
B24: =_xlfn.XLOOKUP(E24,[1]Consolidado!$A:$A,[1]Consolidado!$D:$D) -> 45874 | C24: =IF(I24="TICKET CONCLUÍDO", "Concluído", IF(B24 < TODAY(), "Prazo estourado - " & TODAY()-B24 & " dias atrás", IF(TODAY()+30 < B24, "No prazo - faltam " & B24-TODAY() & " dias", IF(AND(B24-TODAY()<=29, B24-TODAY()>7), "Solicitar dados - faltam " & B24-TODAY() & " dias", IF(B24-TODAY()<=7, "Resolicitar - faltam " & B24-TODAY() & " dias", "Verificar") ) ) ) ) -> Concluído | D24: =_xlfn.XLOOKUP(E24,[1]Consolidado!$A:$A,[1]Consolidado!$AN:$AN) -> 0 | E24: SLU78-JoaoPessoa-MA | F24: =_xlfn.XLOOKUP(E24,'SOLICITAÇÃO DE PAGAMENTO'!C:C,'SOLICITAÇÃO DE PAGAMENTO'!M:M) -> 603440 | G24: 1439 | H24: HENRIQUE | I24: =IF(AND(L24="RESPONSABILIDADE CSC",P24="RESPONSABILIDADE CSC"),"TICKET CONCLUÍDO", "PENDENTE") -> TICKET CONCLUÍDO | J24: 2193601 | K24: 45856 | L24: =IF(J24="","AGUARDANDO DADOS","RESPONSABILIDADE CSC") -> RESPONSABILIDADE CSC | M24: solicitei dados cadastrais aguardando | N24: 2193568 | O24: 45856 | P24: =IF(N24="","AGUARDANDO DADOS","RESPONSABILIDADE CSC") -> RESPONSABILIDADE CSC | Q24: solicitei dados cadastrais aguardando
B25: =_xlfn.XLOOKUP(E25,[1]Consolidado!$A:$A,[1]Consolidado!$D:$D) -> 45889 | C25: =IF(I25="TICKET CONCLUÍDO", "Concluído", IF(B25 < TODAY(), "Prazo estourado - " & TODAY()-B25 & " dias atrás", IF(TODAY()+30 < B25, "No prazo - faltam " & B25-TODAY() & " dias", IF(AND(B25-TODAY()<=29, B25-TODAY()>7), "Solicitar dados - faltam " & B25-TODAY() & " dias", IF(B25-TODAY()<=7, "Resolicitar - faltam " & B25-TODAY() & " dias", "Verificar") ) ) ) ) -> Concluído | D25: =_xlfn.XLOOKUP(E25,[1]Consolidado!$A:$A,[1]Consolidado!$AN:$AN) -> 0 | E25: AGA09-SadocCorrei-TO | F25: =_xlfn.XLOOKUP(E25,'SOLICITAÇÃO DE PAGAMENTO'!C:C,'SOLICITAÇÃO DE PAGAMENTO'!M:M) -> 605482 | G25: 1489 | H25: ANDRE | I25: =IF(AND(L25="RESPONSABILIDADE CSC",P25="RESPONSABILIDADE CSC"),"TICKET CONCLUÍDO", "PENDENTE") -> TICKET CONCLUÍDO | J25: 2271086 | K25: 45869 | L25: =IF(J25="","AGUARDANDO DADOS","RESPONSABILIDADE CSC") -> RESPONSABILIDADE CSC | N25: 2271026 | O25: 45869 | P25: =IF(N25="","AGUARDANDO DADOS","RESPONSABILIDADE CSC") -> RESPONSABILIDADE CSC
B26: =_xlfn.XLOOKUP(E26,[1]Consolidado!$A:$A,[1]Consolidado!$D:$D) -> 45899 | C26: =IF(I26="TICKET CONCLUÍDO", "Concluído", IF(B26 < TODAY(), "Prazo estourado - " & TODAY()-B26 & " dias atrás", IF(TODAY()+30 < B26, "No prazo - faltam " & B26-TODAY() & " dias", IF(AND(B26-TODAY()<=29, B26-TODAY()>7), "Solicitar dados - faltam " & B26-TODAY() & " dias", IF(B26-TODAY()<=7, "Resolicitar - faltam " & B26-TODAY() & " dias", "Verificar") ) ) ) ) -> Concluído | D26: =_xlfn.XLOOKUP(E26,[1]Consolidado!$A:$A,[1]Consolidado!$AN:$AN) -> 0 | E26: ALT03-Brasilia-PA | F26: 603167 | G26: 1492 | H26: HENRIQUE | I26: =IF(AND(L26="RESPONSABILIDADE CSC",P26="RESPONSABILIDADE CSC"),"TICKET CONCLUÍDO", "PENDENTE") -> TICKET CONCLUÍDO | L26: RESPONSABILIDADE CSC | M26: Não haverá cobrança | N26: 2274886 | O26: 45869 | P26: =IF(N26="","AGUARDANDO DADOS","RESPONSABILIDADE CSC") -> RESPONSABILIDADE CSC
B27: =_xlfn.XLOOKUP(E27,[1]Consolidado!$A:$A,[1]Consolidado!$D:$D) -> 45927 | C27: =IF(I27="TICKET CONCLUÍDO", "Concluído", IF(B27 < TODAY(), "Prazo estourado - " & TODAY()-B27 & " dias atrás", IF(TODAY()+30 < B27, "No prazo - faltam " & B27-TODAY() & " dias", IF(AND(B27-TODAY()<=29, B27-TODAY()>7), "Solicitar dados - faltam " & B27-TODAY() & " dias", IF(B27-TODAY()<=7, "Resolicitar - faltam " & B27-TODAY() & " dias", "Verificar") ) ) ) ) -> Concluído | D27: =_xlfn.XLOOKUP(E27,[1]Consolidado!$A:$A,[1]Consolidado!$AN:$AN) -> Atraso emissão da I.E. | E27: CGR08-Quarenta-PB | F27: =_xlfn.XLOOKUP(E27,'SOLICITAÇÃO DE PAGAMENTO'!C:C,'SOLICITAÇÃO DE PAGAMENTO'!M:M) -> 603123 | G27: =_xlfn.XLOOKUP(E27,'SOLICITAÇÃO DE PAGAMENTO'!C:C,'SOLICITAÇÃO DE PAGAMENTO'!B:B,"") -> 1459 | H27: =_xlfn.XLOOKUP(G27,'SOLICITAÇÃO DE PAGAMENTO'!B:B,'SOLICITAÇÃO DE PAGAMENTO'!E:E) -> ANDRE | I27: =IF(AND(L27="RESPONSABILIDADE CSC",P27="RESPONSABILIDADE CSC"),"TICKET CONCLUÍDO", "PENDENTE") -> TICKET CONCLUÍDO | J27: 2436969 | K27: 45896 | L27: =IF(J27="","AGUARDANDO DADOS","RESPONSABILIDADE CSC") -> RESPONSABILIDADE CSC | N27: 2751482 | O27: 45938 | P27: =IF(N27="","AGUARDANDO DADOS","RESPONSABILIDADE CSC") -> RESPONSABILIDADE CSC
B28: =_xlfn.XLOOKUP(E28,[1]Consolidado!$A:$A,[1]Consolidado!$D:$D) -> 45876 | C28: =IF(I28="TICKET CONCLUÍDO", "Concluído", IF(B28 < TODAY(), "Prazo estourado - " & TODAY()-B28 & " dias atrás", IF(TODAY()+30 < B28, "No prazo - faltam " & B28-TODAY() & " dias", IF(AND(B28-TODAY()<=29, B28-TODAY()>7), "Solicitar dados - faltam " & B28-TODAY() & " dias", IF(B28-TODAY()<=7, "Resolicitar - faltam " & B28-TODAY() & " dias", "Verificar") ) ) ) ) -> Concluído | D28: =_xlfn.XLOOKUP(E28,[1]Consolidado!$A:$A,[1]Consolidado!$AN:$AN) -> 0 | E28: FOR192-LesteOeste-CE | F28: =_xlfn.XLOOKUP(E28,'SOLICITAÇÃO DE PAGAMENTO'!C:C,'SOLICITAÇÃO DE PAGAMENTO'!M:M) -> 605741 | G28: =_xlfn.XLOOKUP(E28,'SOLICITAÇÃO DE PAGAMENTO'!C:C,'SOLICITAÇÃO DE PAGAMENTO'!B:B,"") -> 1494 | H28: =_xlfn.XLOOKUP(G28,'SOLICITAÇÃO DE PAGAMENTO'!B:B,'SOLICITAÇÃO DE PAGAMENTO'!E:E,"") -> JORDANA | I28: =IF(AND(L28="RESPONSABILIDADE CSC",P28="RESPONSABILIDADE CSC"),"TICKET CONCLUÍDO", "PENDENTE") -> TICKET CONCLUÍDO | L28: RESPONSABILIDADE CSC | M28: Consumo via poço | N28: 2385189 | O28: 19//08/2025 | P28: =IF(N28="","AGUARDANDO DADOS","RESPONSABILIDADE CSC") -> RESPONSABILIDADE CSC | Q28: solicitei dados cadastrais aguardando
B29: =_xlfn.XLOOKUP(E29,[1]Consolidado!$A:$A,[1]Consolidado!$D:$D) -> 45918 | C29: =IF(I29="TICKET CONCLUÍDO", "Concluído", IF(B29 < TODAY(), "Prazo estourado - " & TODAY()-B29 & " dias atrás", IF(TODAY()+30 < B29, "No prazo - faltam " & B29-TODAY() & " dias", IF(AND(B29-TODAY()<=29, B29-TODAY()>7), "Solicitar dados - faltam " & B29-TODAY() & " dias", IF(B29-TODAY()<=7, "Resolicitar - faltam " & B29-TODAY() & " dias", "Verificar") ) ) ) ) -> Concluído | D29: =_xlfn.XLOOKUP(E29,[1]Consolidado!$A:$A,[1]Consolidado!$AN:$AN) -> Atrasou I.E para envio de mercadoria / Atraso no envio de fardamento | E29: CHP02-15Novembro-MA | F29: =_xlfn.XLOOKUP(E29,'SOLICITAÇÃO DE PAGAMENTO'!C:C,'SOLICITAÇÃO DE PAGAMENTO'!M:M) -> 604328 | G29: =_xlfn.XLOOKUP(E29,'SOLICITAÇÃO DE PAGAMENTO'!C:C,'SOLICITAÇÃO DE PAGAMENTO'!B:B,"") -> 1496 | H29: =_xlfn.XLOOKUP(G29,'SOLICITAÇÃO DE PAGAMENTO'!B:B,'SOLICITAÇÃO DE PAGAMENTO'!E:E,"") -> HENRIQUE | I29: =IF(AND(L29="RESPONSABILIDADE CSC",P29="RESPONSABILIDADE CSC"),"TICKET CONCLUÍDO", "PENDENTE") -> TICKET CONCLUÍDO | J29: 2404923 | K29: 45891 | L29: =IF(J29="","AGUARDANDO DADOS","RESPONSABILIDADE CSC") -> RESPONSABILIDADE CSC | N29: 2404905 | O29: 45891 | P29: =IF(N29="","AGUARDANDO DADOS","RESPONSABILIDADE CSC") -> RESPONSABILIDADE CSC
B30: =_xlfn.XLOOKUP(E30,[1]Consolidado!$A:$A,[1]Consolidado!$D:$D) -> 45917 | C30: =IF(I30="TICKET CONCLUÍDO", "Concluído", IF(B30 < TODAY(), "Prazo estourado - " & TODAY()-B30 & " dias atrás", IF(TODAY()+30 < B30, "No prazo - faltam " & B30-TODAY() & " dias", IF(AND(B30-TODAY()<=29, B30-TODAY()>7), "Solicitar dados - faltam " & B30-TODAY() & " dias", IF(B30-TODAY()<=7, "Resolicitar - faltam " & B30-TODAY() & " dias", "Verificar") ) ) ) ) -> Concluído | D30: =_xlfn.XLOOKUP(E30,[1]Consolidado!$A:$A,[1]Consolidado!$AN:$AN) -> Atraso na contratação farma que gerou atraso nos Alvarás. Erro na inclinação de obra vão resolver após abertura | E30: PRB04-PA160-PA | F30: =_xlfn.XLOOKUP(E30,'SOLICITAÇÃO DE PAGAMENTO'!C:C,'SOLICITAÇÃO DE PAGAMENTO'!M:M) -> 605480 | G30: =_xlfn.XLOOKUP(E30,'SOLICITAÇÃO DE PAGAMENTO'!C:C,'SOLICITAÇÃO DE PAGAMENTO'!B:B,"") -> 1497 | H30: =_xlfn.XLOOKUP(G30,'SOLICITAÇÃO DE PAGAMENTO'!B:B,'SOLICITAÇÃO DE PAGAMENTO'!E:E,"") -> HENRIQUE | I30: =IF(AND(L30="RESPONSABILIDADE CSC",P30="RESPONSABILIDADE CSC"),"TICKET CONCLUÍDO", "PENDENTE") -> TICKET CONCLUÍDO | J30: 2401951 | K30: 45890 | L30: =IF(J30="","AGUARDANDO DADOS","RESPONSABILIDADE CSC") -> RESPONSABILIDADE CSC | N30: 2486560 | O30: 45903 | P30: =IF(N30="","AGUARDANDO DADOS","RESPONSABILIDADE CSC") -> RESPONSABILIDADE CSC
B31: =_xlfn.XLOOKUP(E31,[1]Consolidado!$A:$A,[1]Consolidado!$D:$D) -> 45940 | C31: =IF(I31="TICKET CONCLUÍDO", "Concluído", IF(B31 < TODAY(), "Prazo estourado - " & TODAY()-B31 & " dias atrás", IF(TODAY()+30 < B31, "No prazo - faltam " & B31-TODAY() & " dias", IF(AND(B31-TODAY()<=29, B31-TODAY()>7), "Solicitar dados - faltam " & B31-TODAY() & " dias", IF(B31-TODAY()<=7, "Resolicitar - faltam " & B31-TODAY() & " dias", "Verificar") ) ) ) ) -> Concluído | D31: =_xlfn.XLOOKUP(E31,[1]Consolidado!$A:$A,[1]Consolidado!$AN:$AN) -> controlado liberado 22/09 / Emissão do Alvará de funcionamento segurou a abertura. Pbra executada em desacordo com o projeto aprovado. Atraso significativo na entrega de documentação | E31: TER30-Aeroporto-PI | F31: =_xlfn.XLOOKUP(E31,'SOLICITAÇÃO DE PAGAMENTO'!C:C,'SOLICITAÇÃO DE PAGAMENTO'!M:M) -> 602884 | G31: =_xlfn.XLOOKUP(E31,'SOLICITAÇÃO DE PAGAMENTO'!C:C,'SOLICITAÇÃO DE PAGAMENTO'!B:B,"") -> 1428 | H31: =_xlfn.XLOOKUP(G31,'SOLICITAÇÃO DE PAGAMENTO'!B:B,'SOLICITAÇÃO DE PAGAMENTO'!E:E,"") -> ANDRE | I31: =IF(AND(L31="RESPONSABILIDADE CSC",P31="RESPONSABILIDADE CSC"),"TICKET CONCLUÍDO", "PENDENTE") -> TICKET CONCLUÍDO | J31: 2760018 | K31: 45939 | L31: =IF(J31="","AGUARDANDO DADOS","RESPONSABILIDADE CSC") -> RESPONSABILIDADE CSC | N31: 2759982 | O31: 45939 | P31: =IF(N31="","AGUARDANDO DADOS","RESPONSABILIDADE CSC") -> RESPONSABILIDADE CSC
B32: =_xlfn.XLOOKUP(E32,[1]Consolidado!$A:$A,[1]Consolidado!$D:$D) -> 45976 | C32: =IF(I32="TICKET CONCLUÍDO", "Concluído", IF(B32 < TODAY(), "Prazo estourado - " & TODAY()-B32 & " dias atrás", IF(TODAY()+30 < B32, "No prazo - faltam " & B32-TODAY() & " dias", IF(AND(B32-TODAY()<=29, B32-TODAY()>7), "Solicitar dados - faltam " & B32-TODAY() & " dias", IF(B32-TODAY()<=7, "Resolicitar - faltam " & B32-TODAY() & " dias", "Verificar") ) ) ) ) -> Concluído | D32: =_xlfn.XLOOKUP(E32,[1]Consolidado!$A:$A,[1]Consolidado!$AN:$AN) -> vistoria de vigilância | E32: SLU75-Holandeses-MA | F32: =_xlfn.XLOOKUP(E32,'SOLICITAÇÃO DE PAGAMENTO'!C:C,'SOLICITAÇÃO DE PAGAMENTO'!M:M) -> 603852 | G32: =_xlfn.XLOOKUP(E32,'SOLICITAÇÃO DE PAGAMENTO'!C:C,'SOLICITAÇÃO DE PAGAMENTO'!B:B,"") -> 1476 | H32: =_xlfn.XLOOKUP(G32,'SOLICITAÇÃO DE PAGAMENTO'!B:B,'SOLICITAÇÃO DE PAGAMENTO'!E:E,"") -> HENRIQUE | I32: =IF(AND(L32="RESPONSABILIDADE CSC",P32="RESPONSABILIDADE CSC"),"TICKET CONCLUÍDO", "PENDENTE") -> TICKET CONCLUÍDO | J32: 3048009 | K32: 45973 | L32: =IF(J32="","AGUARDANDO DADOS","RESPONSABILIDADE CSC") -> RESPONSABILIDADE CSC | N32: 3048039 | O32: 45973 | P32: =IF(N32="","AGUARDANDO DADOS","RESPONSABILIDADE CSC") -> RESPONSABILIDADE CSC | Q32: AGUARDANDO PADRAO 12.10
